{
 "cells": [
  {
   "cell_type": "code",
   "execution_count": 9,
   "metadata": {},
   "outputs": [
    {
     "name": "stdout",
     "output_type": "stream",
     "text": [
      "Unexpected exception formatting exception. Falling back to standard exception\n"
     ]
    },
    {
     "name": "stderr",
     "output_type": "stream",
     "text": [
      "Traceback (most recent call last):\n",
      "  File \"C:\\Users\\16788\\AppData\\Roaming\\Python\\Python311\\site-packages\\IPython\\core\\interactiveshell.py\", line 3106, in _run_cell\n",
      "    result = runner(coro)\n",
      "             ^^^^^^^^^^^^\n",
      "  File \"C:\\Users\\16788\\AppData\\Roaming\\Python\\Python311\\site-packages\\IPython\\core\\async_helpers.py\", line 129, in _pseudo_sync_runner\n",
      "    coro.send(None)\n",
      "  File \"C:\\Users\\16788\\AppData\\Roaming\\Python\\Python311\\site-packages\\IPython\\core\\interactiveshell.py\", line 3278, in run_cell_async\n",
      "    cell_name = compiler.cache(cell, self.execution_count, raw_code=raw_cell)\n",
      "                ^^^^^^^^^^^^^^^^^^^^^^^^^^^^^^^^^^^^^^^^^^^^^^^^^^^^^^^^^^^^^\n",
      "  File \"C:\\Users\\16788\\AppData\\Roaming\\Python\\Python311\\site-packages\\IPython\\core\\compilerop.py\", line 155, in cache\n",
      "    name = self.get_code_name(raw_code, transformed_code, number)\n",
      "           ^^^^^^^^^^^^^^^^^^^^^^^^^^^^^^^^^^^^^^^^^^^^^^^^^^^^^^\n",
      "  File \"C:\\Users\\16788\\AppData\\Roaming\\Python\\Python311\\site-packages\\ipykernel\\compiler.py\", line 105, in get_code_name\n",
      "    return get_file_name(raw_code)\n",
      "           ^^^^^^^^^^^^^^^^^^^^^^^\n",
      "  File \"C:\\Users\\16788\\AppData\\Roaming\\Python\\Python311\\site-packages\\ipykernel\\compiler.py\", line 88, in get_file_name\n",
      "    cell_name = os.environ.get(\"IPYKERNEL_CELL_NAME\")\n",
      "                ^^^^^^^^^^^^^^\n",
      "AttributeError: 'str' object has no attribute 'get'\n",
      "\n",
      "During handling of the above exception, another exception occurred:\n",
      "\n",
      "Traceback (most recent call last):\n",
      "  File \"C:\\Users\\16788\\AppData\\Roaming\\Python\\Python311\\site-packages\\IPython\\core\\interactiveshell.py\", line 2144, in showtraceback\n",
      "    stb = self.InteractiveTB.structured_traceback(\n",
      "          ^^^^^^^^^^^^^^^^^^^^^^^^^^^^^^^^^^^^^^^^\n",
      "  File \"C:\\Users\\16788\\AppData\\Roaming\\Python\\Python311\\site-packages\\IPython\\core\\ultratb.py\", line 1448, in structured_traceback\n",
      "    return FormattedTB.structured_traceback(\n",
      "           ^^^^^^^^^^^^^^^^^^^^^^^^^^^^^^^^^\n",
      "  File \"C:\\Users\\16788\\AppData\\Roaming\\Python\\Python311\\site-packages\\IPython\\core\\ultratb.py\", line 1339, in structured_traceback\n",
      "    return VerboseTB.structured_traceback(\n",
      "           ^^^^^^^^^^^^^^^^^^^^^^^^^^^^^^^\n",
      "  File \"C:\\Users\\16788\\AppData\\Roaming\\Python\\Python311\\site-packages\\IPython\\core\\ultratb.py\", line 1186, in structured_traceback\n",
      "    formatted_exception = self.format_exception_as_a_whole(etype, evalue, etb, number_of_lines_of_context,\n",
      "                          ^^^^^^^^^^^^^^^^^^^^^^^^^^^^^^^^^^^^^^^^^^^^^^^^^^^^^^^^^^^^^^^^^^^^^^^^^^^^^^^^\n",
      "  File \"C:\\Users\\16788\\AppData\\Roaming\\Python\\Python311\\site-packages\\IPython\\core\\ultratb.py\", line 1074, in format_exception_as_a_whole\n",
      "    head = self.prepare_header(str(etype), self.long_header)\n",
      "           ^^^^^^^^^^^^^^^^^^^^^^^^^^^^^^^^^^^^^^^^^^^^^^^^^\n",
      "  File \"C:\\Users\\16788\\AppData\\Roaming\\Python\\Python311\\site-packages\\IPython\\core\\ultratb.py\", line 992, in prepare_header\n",
      "    width = min(75, get_terminal_size()[0])\n",
      "                    ^^^^^^^^^^^^^^^^^^^\n",
      "  File \"C:\\Users\\16788\\AppData\\Roaming\\Python\\Python311\\site-packages\\IPython\\utils\\terminal.py\", line 125, in get_terminal_size\n",
      "    return _get_terminal_size((defaultx, defaulty))\n",
      "           ^^^^^^^^^^^^^^^^^^^^^^^^^^^^^^^^^^^^^^^^\n",
      "  File \"c:\\Python311\\Lib\\shutil.py\", line 1408, in get_terminal_size\n",
      "    columns = int(os.environ['COLUMNS'])\n",
      "                  ~~~~~~~~~~^^^^^^^^^^^\n",
      "TypeError: string indices must be integers, not 'str'\n"
     ]
    },
    {
     "name": "stdout",
     "output_type": "stream",
     "text": [
      "ERROR! Session/line number was not unique in database. History logging moved to new session 141\n"
     ]
    }
   ],
   "source": [
    "pip install langchain"
   ]
  },
  {
   "cell_type": "code",
   "execution_count": 9,
   "metadata": {},
   "outputs": [
    {
     "name": "stdout",
     "output_type": "stream",
     "text": [
      "Unexpected exception formatting exception. Falling back to standard exception\n"
     ]
    },
    {
     "name": "stderr",
     "output_type": "stream",
     "text": [
      "Traceback (most recent call last):\n",
      "  File \"C:\\Users\\16788\\AppData\\Roaming\\Python\\Python311\\site-packages\\IPython\\core\\interactiveshell.py\", line 3106, in _run_cell\n",
      "    result = runner(coro)\n",
      "             ^^^^^^^^^^^^\n",
      "  File \"C:\\Users\\16788\\AppData\\Roaming\\Python\\Python311\\site-packages\\IPython\\core\\async_helpers.py\", line 129, in _pseudo_sync_runner\n",
      "    coro.send(None)\n",
      "  File \"C:\\Users\\16788\\AppData\\Roaming\\Python\\Python311\\site-packages\\IPython\\core\\interactiveshell.py\", line 3278, in run_cell_async\n",
      "    cell_name = compiler.cache(cell, self.execution_count, raw_code=raw_cell)\n",
      "                ^^^^^^^^^^^^^^^^^^^^^^^^^^^^^^^^^^^^^^^^^^^^^^^^^^^^^^^^^^^^^\n",
      "  File \"C:\\Users\\16788\\AppData\\Roaming\\Python\\Python311\\site-packages\\IPython\\core\\compilerop.py\", line 155, in cache\n",
      "    name = self.get_code_name(raw_code, transformed_code, number)\n",
      "           ^^^^^^^^^^^^^^^^^^^^^^^^^^^^^^^^^^^^^^^^^^^^^^^^^^^^^^\n",
      "  File \"C:\\Users\\16788\\AppData\\Roaming\\Python\\Python311\\site-packages\\ipykernel\\compiler.py\", line 105, in get_code_name\n",
      "    return get_file_name(raw_code)\n",
      "           ^^^^^^^^^^^^^^^^^^^^^^^\n",
      "  File \"C:\\Users\\16788\\AppData\\Roaming\\Python\\Python311\\site-packages\\ipykernel\\compiler.py\", line 88, in get_file_name\n",
      "    cell_name = os.environ.get(\"IPYKERNEL_CELL_NAME\")\n",
      "                ^^^^^^^^^^^^^^\n",
      "AttributeError: 'str' object has no attribute 'get'\n",
      "\n",
      "During handling of the above exception, another exception occurred:\n",
      "\n",
      "Traceback (most recent call last):\n",
      "  File \"C:\\Users\\16788\\AppData\\Roaming\\Python\\Python311\\site-packages\\IPython\\core\\interactiveshell.py\", line 2144, in showtraceback\n",
      "    stb = self.InteractiveTB.structured_traceback(\n",
      "          ^^^^^^^^^^^^^^^^^^^^^^^^^^^^^^^^^^^^^^^^\n",
      "  File \"C:\\Users\\16788\\AppData\\Roaming\\Python\\Python311\\site-packages\\IPython\\core\\ultratb.py\", line 1448, in structured_traceback\n",
      "    return FormattedTB.structured_traceback(\n",
      "           ^^^^^^^^^^^^^^^^^^^^^^^^^^^^^^^^^\n",
      "  File \"C:\\Users\\16788\\AppData\\Roaming\\Python\\Python311\\site-packages\\IPython\\core\\ultratb.py\", line 1339, in structured_traceback\n",
      "    return VerboseTB.structured_traceback(\n",
      "           ^^^^^^^^^^^^^^^^^^^^^^^^^^^^^^^\n",
      "  File \"C:\\Users\\16788\\AppData\\Roaming\\Python\\Python311\\site-packages\\IPython\\core\\ultratb.py\", line 1186, in structured_traceback\n",
      "    formatted_exception = self.format_exception_as_a_whole(etype, evalue, etb, number_of_lines_of_context,\n",
      "                          ^^^^^^^^^^^^^^^^^^^^^^^^^^^^^^^^^^^^^^^^^^^^^^^^^^^^^^^^^^^^^^^^^^^^^^^^^^^^^^^^\n",
      "  File \"C:\\Users\\16788\\AppData\\Roaming\\Python\\Python311\\site-packages\\IPython\\core\\ultratb.py\", line 1074, in format_exception_as_a_whole\n",
      "    head = self.prepare_header(str(etype), self.long_header)\n",
      "           ^^^^^^^^^^^^^^^^^^^^^^^^^^^^^^^^^^^^^^^^^^^^^^^^^\n",
      "  File \"C:\\Users\\16788\\AppData\\Roaming\\Python\\Python311\\site-packages\\IPython\\core\\ultratb.py\", line 992, in prepare_header\n",
      "    width = min(75, get_terminal_size()[0])\n",
      "                    ^^^^^^^^^^^^^^^^^^^\n",
      "  File \"C:\\Users\\16788\\AppData\\Roaming\\Python\\Python311\\site-packages\\IPython\\utils\\terminal.py\", line 125, in get_terminal_size\n",
      "    return _get_terminal_size((defaultx, defaulty))\n",
      "           ^^^^^^^^^^^^^^^^^^^^^^^^^^^^^^^^^^^^^^^^\n",
      "  File \"c:\\Python311\\Lib\\shutil.py\", line 1408, in get_terminal_size\n",
      "    columns = int(os.environ['COLUMNS'])\n",
      "                  ~~~~~~~~~~^^^^^^^^^^^\n",
      "TypeError: string indices must be integers, not 'str'\n"
     ]
    },
    {
     "name": "stdout",
     "output_type": "stream",
     "text": [
      "ERROR! Session/line number was not unique in database. History logging moved to new session 140\n"
     ]
    }
   ],
   "source": [
    "import getpass\n",
    "import os\n",
    "\n",
    "os.environ[\"LANGCHAIN_TRACING_V2\"] = \"true\"\n",
    "os.environ[\"LANGCHAIN_API_KEY\"] = getpass.getpass()"
   ]
  },
  {
   "cell_type": "code",
   "execution_count": 9,
   "metadata": {},
   "outputs": [
    {
     "name": "stdout",
     "output_type": "stream",
     "text": [
      "Unexpected exception formatting exception. Falling back to standard exception\n"
     ]
    },
    {
     "name": "stderr",
     "output_type": "stream",
     "text": [
      "Traceback (most recent call last):\n",
      "  File \"C:\\Users\\16788\\AppData\\Roaming\\Python\\Python311\\site-packages\\IPython\\core\\interactiveshell.py\", line 3106, in _run_cell\n",
      "    result = runner(coro)\n",
      "             ^^^^^^^^^^^^\n",
      "  File \"C:\\Users\\16788\\AppData\\Roaming\\Python\\Python311\\site-packages\\IPython\\core\\async_helpers.py\", line 129, in _pseudo_sync_runner\n",
      "    coro.send(None)\n",
      "  File \"C:\\Users\\16788\\AppData\\Roaming\\Python\\Python311\\site-packages\\IPython\\core\\interactiveshell.py\", line 3278, in run_cell_async\n",
      "    cell_name = compiler.cache(cell, self.execution_count, raw_code=raw_cell)\n",
      "                ^^^^^^^^^^^^^^^^^^^^^^^^^^^^^^^^^^^^^^^^^^^^^^^^^^^^^^^^^^^^^\n",
      "  File \"C:\\Users\\16788\\AppData\\Roaming\\Python\\Python311\\site-packages\\IPython\\core\\compilerop.py\", line 155, in cache\n",
      "    name = self.get_code_name(raw_code, transformed_code, number)\n",
      "           ^^^^^^^^^^^^^^^^^^^^^^^^^^^^^^^^^^^^^^^^^^^^^^^^^^^^^^\n",
      "  File \"C:\\Users\\16788\\AppData\\Roaming\\Python\\Python311\\site-packages\\ipykernel\\compiler.py\", line 105, in get_code_name\n",
      "    return get_file_name(raw_code)\n",
      "           ^^^^^^^^^^^^^^^^^^^^^^^\n",
      "  File \"C:\\Users\\16788\\AppData\\Roaming\\Python\\Python311\\site-packages\\ipykernel\\compiler.py\", line 88, in get_file_name\n",
      "    cell_name = os.environ.get(\"IPYKERNEL_CELL_NAME\")\n",
      "                ^^^^^^^^^^^^^^\n",
      "AttributeError: 'str' object has no attribute 'get'\n",
      "\n",
      "During handling of the above exception, another exception occurred:\n",
      "\n",
      "Traceback (most recent call last):\n",
      "  File \"C:\\Users\\16788\\AppData\\Roaming\\Python\\Python311\\site-packages\\IPython\\core\\interactiveshell.py\", line 2144, in showtraceback\n",
      "    stb = self.InteractiveTB.structured_traceback(\n",
      "          ^^^^^^^^^^^^^^^^^^^^^^^^^^^^^^^^^^^^^^^^\n",
      "  File \"C:\\Users\\16788\\AppData\\Roaming\\Python\\Python311\\site-packages\\IPython\\core\\ultratb.py\", line 1448, in structured_traceback\n",
      "    return FormattedTB.structured_traceback(\n",
      "           ^^^^^^^^^^^^^^^^^^^^^^^^^^^^^^^^^\n",
      "  File \"C:\\Users\\16788\\AppData\\Roaming\\Python\\Python311\\site-packages\\IPython\\core\\ultratb.py\", line 1339, in structured_traceback\n",
      "    return VerboseTB.structured_traceback(\n",
      "           ^^^^^^^^^^^^^^^^^^^^^^^^^^^^^^^\n",
      "  File \"C:\\Users\\16788\\AppData\\Roaming\\Python\\Python311\\site-packages\\IPython\\core\\ultratb.py\", line 1186, in structured_traceback\n",
      "    formatted_exception = self.format_exception_as_a_whole(etype, evalue, etb, number_of_lines_of_context,\n",
      "                          ^^^^^^^^^^^^^^^^^^^^^^^^^^^^^^^^^^^^^^^^^^^^^^^^^^^^^^^^^^^^^^^^^^^^^^^^^^^^^^^^\n",
      "  File \"C:\\Users\\16788\\AppData\\Roaming\\Python\\Python311\\site-packages\\IPython\\core\\ultratb.py\", line 1074, in format_exception_as_a_whole\n",
      "    head = self.prepare_header(str(etype), self.long_header)\n",
      "           ^^^^^^^^^^^^^^^^^^^^^^^^^^^^^^^^^^^^^^^^^^^^^^^^^\n",
      "  File \"C:\\Users\\16788\\AppData\\Roaming\\Python\\Python311\\site-packages\\IPython\\core\\ultratb.py\", line 992, in prepare_header\n",
      "    width = min(75, get_terminal_size()[0])\n",
      "                    ^^^^^^^^^^^^^^^^^^^\n",
      "  File \"C:\\Users\\16788\\AppData\\Roaming\\Python\\Python311\\site-packages\\IPython\\utils\\terminal.py\", line 125, in get_terminal_size\n",
      "    return _get_terminal_size((defaultx, defaulty))\n",
      "           ^^^^^^^^^^^^^^^^^^^^^^^^^^^^^^^^^^^^^^^^\n",
      "  File \"c:\\Python311\\Lib\\shutil.py\", line 1408, in get_terminal_size\n",
      "    columns = int(os.environ['COLUMNS'])\n",
      "                  ~~~~~~~~~~^^^^^^^^^^^\n",
      "TypeError: string indices must be integers, not 'str'\n"
     ]
    },
    {
     "name": "stdout",
     "output_type": "stream",
     "text": [
      "ERROR! Session/line number was not unique in database. History logging moved to new session 139\n"
     ]
    }
   ],
   "source": [
    "pip install -qU langchain-openai"
   ]
  },
  {
   "cell_type": "code",
   "execution_count": 9,
   "metadata": {},
   "outputs": [
    {
     "name": "stdout",
     "output_type": "stream",
     "text": [
      "Unexpected exception formatting exception. Falling back to standard exception\n"
     ]
    },
    {
     "name": "stderr",
     "output_type": "stream",
     "text": [
      "Traceback (most recent call last):\n",
      "  File \"C:\\Users\\16788\\AppData\\Roaming\\Python\\Python311\\site-packages\\IPython\\core\\interactiveshell.py\", line 3106, in _run_cell\n",
      "    result = runner(coro)\n",
      "             ^^^^^^^^^^^^\n",
      "  File \"C:\\Users\\16788\\AppData\\Roaming\\Python\\Python311\\site-packages\\IPython\\core\\async_helpers.py\", line 129, in _pseudo_sync_runner\n",
      "    coro.send(None)\n",
      "  File \"C:\\Users\\16788\\AppData\\Roaming\\Python\\Python311\\site-packages\\IPython\\core\\interactiveshell.py\", line 3278, in run_cell_async\n",
      "    cell_name = compiler.cache(cell, self.execution_count, raw_code=raw_cell)\n",
      "                ^^^^^^^^^^^^^^^^^^^^^^^^^^^^^^^^^^^^^^^^^^^^^^^^^^^^^^^^^^^^^\n",
      "  File \"C:\\Users\\16788\\AppData\\Roaming\\Python\\Python311\\site-packages\\IPython\\core\\compilerop.py\", line 155, in cache\n",
      "    name = self.get_code_name(raw_code, transformed_code, number)\n",
      "           ^^^^^^^^^^^^^^^^^^^^^^^^^^^^^^^^^^^^^^^^^^^^^^^^^^^^^^\n",
      "  File \"C:\\Users\\16788\\AppData\\Roaming\\Python\\Python311\\site-packages\\ipykernel\\compiler.py\", line 105, in get_code_name\n",
      "    return get_file_name(raw_code)\n",
      "           ^^^^^^^^^^^^^^^^^^^^^^^\n",
      "  File \"C:\\Users\\16788\\AppData\\Roaming\\Python\\Python311\\site-packages\\ipykernel\\compiler.py\", line 88, in get_file_name\n",
      "    cell_name = os.environ.get(\"IPYKERNEL_CELL_NAME\")\n",
      "                ^^^^^^^^^^^^^^\n",
      "AttributeError: 'str' object has no attribute 'get'\n",
      "\n",
      "During handling of the above exception, another exception occurred:\n",
      "\n",
      "Traceback (most recent call last):\n",
      "  File \"C:\\Users\\16788\\AppData\\Roaming\\Python\\Python311\\site-packages\\IPython\\core\\interactiveshell.py\", line 2144, in showtraceback\n",
      "    stb = self.InteractiveTB.structured_traceback(\n",
      "          ^^^^^^^^^^^^^^^^^^^^^^^^^^^^^^^^^^^^^^^^\n",
      "  File \"C:\\Users\\16788\\AppData\\Roaming\\Python\\Python311\\site-packages\\IPython\\core\\ultratb.py\", line 1448, in structured_traceback\n",
      "    return FormattedTB.structured_traceback(\n",
      "           ^^^^^^^^^^^^^^^^^^^^^^^^^^^^^^^^^\n",
      "  File \"C:\\Users\\16788\\AppData\\Roaming\\Python\\Python311\\site-packages\\IPython\\core\\ultratb.py\", line 1339, in structured_traceback\n",
      "    return VerboseTB.structured_traceback(\n",
      "           ^^^^^^^^^^^^^^^^^^^^^^^^^^^^^^^\n",
      "  File \"C:\\Users\\16788\\AppData\\Roaming\\Python\\Python311\\site-packages\\IPython\\core\\ultratb.py\", line 1186, in structured_traceback\n",
      "    formatted_exception = self.format_exception_as_a_whole(etype, evalue, etb, number_of_lines_of_context,\n",
      "                          ^^^^^^^^^^^^^^^^^^^^^^^^^^^^^^^^^^^^^^^^^^^^^^^^^^^^^^^^^^^^^^^^^^^^^^^^^^^^^^^^\n",
      "  File \"C:\\Users\\16788\\AppData\\Roaming\\Python\\Python311\\site-packages\\IPython\\core\\ultratb.py\", line 1074, in format_exception_as_a_whole\n",
      "    head = self.prepare_header(str(etype), self.long_header)\n",
      "           ^^^^^^^^^^^^^^^^^^^^^^^^^^^^^^^^^^^^^^^^^^^^^^^^^\n",
      "  File \"C:\\Users\\16788\\AppData\\Roaming\\Python\\Python311\\site-packages\\IPython\\core\\ultratb.py\", line 992, in prepare_header\n",
      "    width = min(75, get_terminal_size()[0])\n",
      "                    ^^^^^^^^^^^^^^^^^^^\n",
      "  File \"C:\\Users\\16788\\AppData\\Roaming\\Python\\Python311\\site-packages\\IPython\\utils\\terminal.py\", line 125, in get_terminal_size\n",
      "    return _get_terminal_size((defaultx, defaulty))\n",
      "           ^^^^^^^^^^^^^^^^^^^^^^^^^^^^^^^^^^^^^^^^\n",
      "  File \"c:\\Python311\\Lib\\shutil.py\", line 1408, in get_terminal_size\n",
      "    columns = int(os.environ['COLUMNS'])\n",
      "                  ~~~~~~~~~~^^^^^^^^^^^\n",
      "TypeError: string indices must be integers, not 'str'\n"
     ]
    },
    {
     "name": "stdout",
     "output_type": "stream",
     "text": [
      "ERROR! Session/line number was not unique in database. History logging moved to new session 138\n"
     ]
    }
   ],
   "source": [
    "print(\"mynameis\")"
   ]
  }
 ],
 "metadata": {
  "kernelspec": {
   "display_name": "Python 3",
   "language": "python",
   "name": "python3"
  },
  "language_info": {
   "codemirror_mode": {
    "name": "ipython",
    "version": 3
   },
   "file_extension": ".py",
   "mimetype": "text/x-python",
   "name": "python",
   "nbconvert_exporter": "python",
   "pygments_lexer": "ipython3",
   "version": "3.11.3"
  }
 },
 "nbformat": 4,
 "nbformat_minor": 2
}
